// what is the output? and explain why?

// 1
Promise.resolve(1)
  .then(res => {
    console.log(res);
    return 2;
  })
  .catch(err => {
    return 3;
  })
  .then(res => {
    console.log(res);
  });

  //output :  1  2
  //The promise executor function runs, passing resolve return value
  //then logged res 1
  //then pass 2 to 2nd then 
  //then logged res === 2

// // 2
Promise.reject(1)
  .then(res => {
    console.log(res);
    return 2;
  })
  .catch(err => {
    console.log(err);
    return 3;
  })
  .then(res => {
    console.log(res);
  });
  // output 1 3 
  // Promise.reject would go to catch the log 1 and then pass return value e to res then log 3

//3
function runAsync(x) {
  const p = new Promise(resolve =>
    setTimeout(() => resolve(x), 1000)
  );
  return p;
}

function runReject(x) {
  const p = new Promise((resolve, reject) =>
    setTimeout(() => reject(`Error: ${x}`), 1000 * x)
  );
  return p;
}

Promise.all([runAsync(1), runReject(4), runAsync(3), runReject(2)])
  .then(res => console.log(res))
  .catch(err => console.log(err));

//output Error:2
//Promise.all would wait all promise to fulfill
//while the one promise reject happen it will immediately reject
//the runReject(2) would be the first reject promise